[2025-01-06T23:29:19.226+0000] {taskinstance.py:1956} INFO - Dependencies all met for dep_context=non-requeueable deps ti=<TaskInstance: dag_insert_log.sql_md_account_d manual__2025-01-06T23:28:13.745960+00:00 [queued]>
[2025-01-06T23:29:19.285+0000] {taskinstance.py:1956} INFO - Dependencies all met for dep_context=requeueable deps ti=<TaskInstance: dag_insert_log.sql_md_account_d manual__2025-01-06T23:28:13.745960+00:00 [queued]>
[2025-01-06T23:29:19.287+0000] {taskinstance.py:2170} INFO - Starting attempt 1 of 2
[2025-01-06T23:29:19.355+0000] {taskinstance.py:2191} INFO - Executing <Task(SQLExecuteQueryOperator): sql_md_account_d> on 2025-01-06 23:28:13.745960+00:00
[2025-01-06T23:29:19.379+0000] {standard_task_runner.py:60} INFO - Started process 453 to run task
[2025-01-06T23:29:19.395+0000] {standard_task_runner.py:87} INFO - Running: ['***', 'tasks', 'run', 'dag_insert_log', 'sql_md_account_d', 'manual__2025-01-06T23:28:13.745960+00:00', '--job-id', '26', '--raw', '--subdir', 'DAGS_FOLDER/dag_insert_log.py', '--cfg-path', '/tmp/tmpeny7x998']
[2025-01-06T23:29:19.400+0000] {standard_task_runner.py:88} INFO - Job 26: Subtask sql_md_account_d
[2025-01-06T23:29:19.578+0000] {task_command.py:423} INFO - Running <TaskInstance: dag_insert_log.sql_md_account_d manual__2025-01-06T23:28:13.745960+00:00 [running]> on host 22295d32c47d
[2025-01-06T23:29:20.202+0000] {taskinstance.py:2480} INFO - Exporting env vars: AIRFLOW_CTX_DAG_OWNER='saida' AIRFLOW_CTX_DAG_ID='dag_insert_log' AIRFLOW_CTX_TASK_ID='sql_md_account_d' AIRFLOW_CTX_EXECUTION_DATE='2025-01-06T23:28:13.745960+00:00' AIRFLOW_CTX_TRY_NUMBER='1' AIRFLOW_CTX_DAG_RUN_ID='manual__2025-01-06T23:28:13.745960+00:00'
[2025-01-06T23:29:20.213+0000] {sql.py:276} INFO - Executing: CALL ds.stage_to_md_account_d();
[2025-01-06T23:29:20.241+0000] {base.py:83} INFO - Using connection ID '***-db' for task execution.
[2025-01-06T23:29:20.302+0000] {base.py:83} INFO - Using connection ID '***-db' for task execution.
[2025-01-06T23:29:20.588+0000] {sql.py:450} INFO - Running statement: CALL ds.stage_to_md_account_d();, parameters: None
[2025-01-06T23:29:20.679+0000] {taskinstance.py:2698} ERROR - Task failed with exception
Traceback (most recent call last):
  File "/home/airflow/.local/lib/python3.8/site-packages/airflow/models/taskinstance.py", line 433, in _execute_task
    result = execute_callable(context=context, **execute_callable_kwargs)
  File "/home/airflow/.local/lib/python3.8/site-packages/airflow/providers/common/sql/operators/sql.py", line 282, in execute
    output = hook.run(
  File "/home/airflow/.local/lib/python3.8/site-packages/airflow/providers/common/sql/hooks/sql.py", line 398, in run
    self._run_command(cur, sql_statement, parameters)
  File "/home/airflow/.local/lib/python3.8/site-packages/airflow/providers/common/sql/hooks/sql.py", line 455, in _run_command
    cur.execute(sql_statement)
psycopg2.errors.RaiseException: ОШИБКА:  Ошибка: команда ON CONFLICT DO UPDATE не может подействовать на строку дважды
CONTEXT:  функция PL/pgSQL ds.stage_to_md_account_d(), строка 41, оператор RAISE

[2025-01-06T23:29:20.777+0000] {taskinstance.py:1138} INFO - Marking task as UP_FOR_RETRY. dag_id=dag_insert_log, task_id=sql_md_account_d, execution_date=20250106T232813, start_date=20250106T232919, end_date=20250106T232920
[2025-01-06T23:29:20.920+0000] {standard_task_runner.py:107} ERROR - Failed to execute job 26 for task sql_md_account_d (ОШИБКА:  Ошибка: команда ON CONFLICT DO UPDATE не может подействовать на строку дважды
CONTEXT:  функция PL/pgSQL ds.stage_to_md_account_d(), строка 41, оператор RAISE
; 453)
[2025-01-06T23:29:21.051+0000] {local_task_job_runner.py:234} INFO - Task exited with return code 1
[2025-01-06T23:29:21.268+0000] {taskinstance.py:3280} INFO - 0 downstream tasks scheduled from follow-on schedule check
