[2025-01-06T23:29:18.904+0000] {taskinstance.py:1956} INFO - Dependencies all met for dep_context=non-requeueable deps ti=<TaskInstance: dag_insert_log.sql_md_exchange_rate_d manual__2025-01-06T23:28:13.745960+00:00 [queued]>
[2025-01-06T23:29:18.930+0000] {taskinstance.py:1956} INFO - Dependencies all met for dep_context=requeueable deps ti=<TaskInstance: dag_insert_log.sql_md_exchange_rate_d manual__2025-01-06T23:28:13.745960+00:00 [queued]>
[2025-01-06T23:29:18.931+0000] {taskinstance.py:2170} INFO - Starting attempt 1 of 2
[2025-01-06T23:29:19.009+0000] {taskinstance.py:2191} INFO - Executing <Task(SQLExecuteQueryOperator): sql_md_exchange_rate_d> on 2025-01-06 23:28:13.745960+00:00
[2025-01-06T23:29:19.051+0000] {standard_task_runner.py:60} INFO - Started process 452 to run task
[2025-01-06T23:29:19.060+0000] {standard_task_runner.py:87} INFO - Running: ['***', 'tasks', 'run', 'dag_insert_log', 'sql_md_exchange_rate_d', 'manual__2025-01-06T23:28:13.745960+00:00', '--job-id', '25', '--raw', '--subdir', 'DAGS_FOLDER/dag_insert_log.py', '--cfg-path', '/tmp/tmpiuwztjwz']
[2025-01-06T23:29:19.090+0000] {standard_task_runner.py:88} INFO - Job 25: Subtask sql_md_exchange_rate_d
[2025-01-06T23:29:19.302+0000] {task_command.py:423} INFO - Running <TaskInstance: dag_insert_log.sql_md_exchange_rate_d manual__2025-01-06T23:28:13.745960+00:00 [running]> on host 22295d32c47d
[2025-01-06T23:29:19.746+0000] {taskinstance.py:2480} INFO - Exporting env vars: AIRFLOW_CTX_DAG_OWNER='saida' AIRFLOW_CTX_DAG_ID='dag_insert_log' AIRFLOW_CTX_TASK_ID='sql_md_exchange_rate_d' AIRFLOW_CTX_EXECUTION_DATE='2025-01-06T23:28:13.745960+00:00' AIRFLOW_CTX_TRY_NUMBER='1' AIRFLOW_CTX_DAG_RUN_ID='manual__2025-01-06T23:28:13.745960+00:00'
[2025-01-06T23:29:19.756+0000] {sql.py:276} INFO - Executing: CALL ds.stage_to_md_exchange_rate_d();
[2025-01-06T23:29:19.813+0000] {base.py:83} INFO - Using connection ID '***-db' for task execution.
[2025-01-06T23:29:19.862+0000] {base.py:83} INFO - Using connection ID '***-db' for task execution.
[2025-01-06T23:29:20.058+0000] {sql.py:450} INFO - Running statement: CALL ds.stage_to_md_exchange_rate_d();, parameters: None
[2025-01-06T23:29:20.109+0000] {taskinstance.py:2698} ERROR - Task failed with exception
Traceback (most recent call last):
  File "/home/airflow/.local/lib/python3.8/site-packages/airflow/models/taskinstance.py", line 433, in _execute_task
    result = execute_callable(context=context, **execute_callable_kwargs)
  File "/home/airflow/.local/lib/python3.8/site-packages/airflow/providers/common/sql/operators/sql.py", line 282, in execute
    output = hook.run(
  File "/home/airflow/.local/lib/python3.8/site-packages/airflow/providers/common/sql/hooks/sql.py", line 398, in run
    self._run_command(cur, sql_statement, parameters)
  File "/home/airflow/.local/lib/python3.8/site-packages/airflow/providers/common/sql/hooks/sql.py", line 455, in _run_command
    cur.execute(sql_statement)
psycopg2.errors.RaiseException: ОШИБКА:  Ошибка: команда ON CONFLICT DO UPDATE не может подействовать на строку дважды
CONTEXT:  функция PL/pgSQL ds.stage_to_md_exchange_rate_d(), строка 27, оператор RAISE

[2025-01-06T23:29:20.141+0000] {taskinstance.py:1138} INFO - Marking task as UP_FOR_RETRY. dag_id=dag_insert_log, task_id=sql_md_exchange_rate_d, execution_date=20250106T232813, start_date=20250106T232918, end_date=20250106T232920
[2025-01-06T23:29:20.262+0000] {standard_task_runner.py:107} ERROR - Failed to execute job 25 for task sql_md_exchange_rate_d (ОШИБКА:  Ошибка: команда ON CONFLICT DO UPDATE не может подействовать на строку дважды
CONTEXT:  функция PL/pgSQL ds.stage_to_md_exchange_rate_d(), строка 27, оператор RAISE
; 452)
[2025-01-06T23:29:20.331+0000] {local_task_job_runner.py:234} INFO - Task exited with return code 1
[2025-01-06T23:29:20.566+0000] {taskinstance.py:3280} INFO - 0 downstream tasks scheduled from follow-on schedule check
